Workbook

Sheet Sheet1
A1: 44867 | B1: 44868
A2: 220 | B2: 370
A3: 1086.9 | B3: 1051.9 | C3: Payroll Cycle | D3: Payroll Value | E3: Cash Rewards | F3: Expenses
C4: January
A5: 1315.74 | B5: 1446.05 | C5: 903 | D5: ='January 2023'!H16 -> 46805.93
A6: 170 | B6: 110 | C6: 906 | D6: ='January 2023'!H35 -> 52030.03
A7: 180 | B7: 295 | C7: 907 | D7: ='January 2023'!H54 -> 50342.84
A8: 147.45 | B8: 835 | C8: 908 | D8: ='January 2023'!H73 -> 49111.96
A9: 215 | B9: 110 | C9: 909 | D9: ='January 2023'!H92 -> 47825.8
A10: 533.1 | B10: 147.45 | D10: =SUM(D5:D9) -> 246116.56
A11: 165 | B11: 330 | C11: February
A12: 430 | B12: 183.1 | C12: 910 | D12: ='February 2023'!H18 -> 49617.56
B13: 165 | C13: 911 | D13: ='February 2023'!H40 -> 46368.83 | E13: ='February 2023'!Z40 -> 37864 | F13: ='February 2023'!Z41 -> 2915
B14: 220 | C14: 912 | D14: ='February 2023'!H59 -> 50182.41 | E14: ='February 2023'!Z59 -> 36792 | F14: ='February 2023'!Z60 -> 2844.5
C15: 913 | D15: ='February 2023'!H78 -> 49032.8 | E15: ='February 2023'!Z78 -> 37582 | F15: ='February 2023'!Z79 -> 8771.5
D16: =SUM(D12:D15) -> 195201.6 | E16: =SUM(E12:E15) -> 112238 | F16: =SUM(F12:F15) -> 14531
C17: March
C18: 914
A19: =SUM(A2:A18) -> 4463.19 | B19: =SUM(B2:B18) -> 5263.5
A20: 4463.19 | B20: 5263.5
A21: =A19-A20 -> 0 | B21: =B19-B20 -> 0
A25: 44874 | B25: 44875
A26: 185 | B26: 405
A27: 1171.9 | B27: 1271.9
A28: 1315.74 | B28: 1355.43
A29: 275 | B29: 195
A30: 110 | B30: 110
A31: 147.45 | B31: 222.45
A32: 140 | B32: 130
A33: 513.1 | B33: 423.1
A34: 165 | B34: 180
A35: 320 | B35: 280
A36: 110
A42: =SUM(A26:A41) -> 4453.19 | B42: =SUM(B26:B41) -> 4572.88
A43: 4453.19 | B43: 4572.88
A44: =A42-A43 -> 0 | B44: =B42-B43 -> 0

Sheet Sheet2
V1: 44888 | W1: 44889 | X1: 44890 | Y1: 44891 | Z1: 44892 | AA1: 44893 | AB1: 44894
V2: 110 | W2: 185 | X2: 295 | Y2: 150 | Z2: 945 | AA2: 440 | AB2: 260
V3: 1566.9 | W3: 1551.9 | X3: 110 | Y3: 958.45 | Z3: 280 | AA3: 835 | AB3: 1196.9
V4: 1230.53 | W4: 1446.05 | X4: 1376.9 | Y4: 220 | Z4: 330 | AA4: 1485.74 | AB4: 1315.53
V5: 220 | W5: 305 | X5: 1446.05 | Y5: 380 | AA5: 75 | AB5: 85
V6: 110 | W6: 147.45 | X6: 220 | Y6: 110 | AA6: 195 | AB6: 305
V7: 147.45 | W7: 235 | X7: 110 | Y7: 265 | AA7: 305 | AB7: 85
V8: 290 | W8: 293.1 | X8: 147.45 | Y8: 431.55 | AA8: 110 | AB8: 110
V9: 403.1 | W9: 75 | X9: 105 | AA9: 147.45 | AB9: 147.45
V10: 165 | X10: 183.1 | AA10: 115 | AB10: 280
V11: 170 | X11: 165 | AA11: 110 | AB11: 293.1
V12: 40 | X12: 320 | AA12: 150 | AB12: 165
AA13: 110 | AB13: 5489.88
AB14: 3690.2
AB15: 589.8
AB16: 5535.3
AB17: 3150
AB18: 1253.72
AB19: 700
V21: =SUM(V2:V20) -> 4452.98 | W21: =SUM(W2:W20) -> 4238.5 | X21: =SUM(X2:X20) -> 4478.5 | Y21: =SUM(Y2:Y20) -> 2515 | Z21: =SUM(Z2:Z20) -> 1555 | AA21: =SUM(AA2:AA20) -> 4078.19 | AB21: =SUM(AB2:AB20) -> 24651.88 | AC21: =SUM(V21:AB21) -> 45970.05
V22: 4452.98 | W22: 4238.5 | X22: 4478.5 | Y22: 2515 | Z22: 1555 | AA22: 4078.19 | AB22: 4242.98 | AC22: 45970.05
V23: =V21-V22 -> 0 | W23: =W21-W22 -> 0 | X23: =X21-X22 -> 0 | Y23: =Y21-Y22 -> 0 | Z23: =Z21-Z22 -> 0 | AA23: =AA21-AA22 -> 0 | AB23: =AB21-AB22 -> 20408.9
AC24: =AC22-AC21 -> 0
V26: 44895 | W26: 44896 | X26: 44897 | Y26: 44898 | Z26: 44899 | AA26: 44900 | AB26: 44901
V27: 570 | W27: 515 | X27: 405 | Y27: 220 | Z27: 280 | AA27: 185 | AB27: 220
V28: 1116.9 | W28: 1080 | X28: 1005 | Y28: 1111.9 | Z28: 75 | AA28: 1016.9 | AB28: 110
V29: 1230.53 | W29: 1675.43 | X29: 1644.5 | Y29: 270 | Z29: 550 | AA29: 1485.74 | AB29: 1101.9 | AF29: 4990.8
V30: 75 | W30: 85 | X30: 110 | Y30: 75 | Z30: 75 | AA30: 110 | AB30: 1640.12 | AF30: 3690.2
V31: 110 | W31: 465 | X31: 85 | Y31: 305 | Z31: 75 | AA31: 180
V32: 147.45 | W32: 965 | X32: 232.45 | Y32: 1100.82 | AA32: 295 | AB32: 305 | AF32: 3500
V33: 145 | W33: 222.45 | X33: 210 | Y33: 225 | AA33: 110 | AB33: 110 | AF33: 1253.72
V34: 533.1 | W34: 130 | X34: 110 | Y34: 403.1 | AA34: 147.45 | AB34: 222.45 | AF34: 5535.3
V35: 150 | W35: 350 | X35: 90 | AA35: 195 | AB35: 145 | AF35: 215.52
W36: 130 | X36: 300 | AA36: 403.1 | AB36: 73.1 | AF36: 0
AA37: 180 | AB37: 165 | AF37: =SUM(AF29:AF36) -> 19185.54
AA38: 150 | AB38: =AF37 -> 19185.54
AA39: 110
V41: =SUM(V27:V40) -> 4077.98 | W41: =SUM(W27:W40) -> 5617.88 | X41: =SUM(X27:X40) -> 4191.95 | Y41: =SUM(Y27:Y40) -> 3710.82 | Z41: =SUM(Z27:Z40) -> 1055 | AA41: =SUM(AA27:AA40) -> 4568.19 | AB41: =SUM(AB27:AB40) -> 23278.11 | AC41: =SUM(V41:AB41) -> 46499.93
V42: 4077.98 | W42: 5617.88 | X42: 4191.95 | Y42: 3710.82 | Z42: 1055 | AA42: 4568.19 | AB42: 23278.11 | AC42: 46499.93
V43: =V41-V42 -> 0 | W43: =W41-W42 -> 0 | X43: =X41-X42 -> 0 | Y43: =Y41-Y42 -> 0 | Z43: =Z41-Z42 -> 0 | AA43: =AA41-AA42 -> 0 | AB43: =AB41-AB42 -> 0
...

Sheet January 2023
A1: 44923 | B1: 44924 | C1: 44925 | D1: 44926 | E1: 44927 | F1: 44928 | G1: 44929 | I1: Registers
A2: 515 | B2: 440 | C2: 358.45 | D2: 330 | E2: 520 | F2: 618.45 | G2: 330 | I2: 2830
A3: 1283.45 | B3: 440 | C3: 570 | D3: 1141.9 | E3: 330 | F3: 606.9 | G3: 525.35 | I3: 700
A4: 1746.05 | B4: 841.9 | C4: 1068.45 | D4: 1128.6 | F4: 1090.35 | G4: 1293.8 | I4: 4990.8
A5: 60 | B5: 1445.53 | C5: 1436.05 | D5: 185 | G5: 1576.05 | I5: 589.8
A6: 147.45 | B6: 75 | C6: 105 | D6: 305 | F6: 110 | G6: 195 | I6: =3690.2+1548.62 -> 5238.82
A7: 120 | B7: 370 | C7: 110 | D7: 185 | F7: 330 | G7: 380 | I7: 4059.22
A8: 146.55 | B8: 222.45 | C8: 222.45 | D8: 255.21 | F8: 305 | G8: 110 | I8: =SUM(I2:I7) -> 18408.64
A9: 150 | B9: 325 | C9: 235 | D9: 345 | F9: 185 | G9: 147.45
A10: 60 | B10: 533.1 | C10: 313.1 | D10: 403.1 | F10: 145 | G10: 310
A11: 220 | B11: 165 | C11: 180 | F11: 454.3 | G11: 390.85
F12: 90 | G12: 150
F13: 20
A16: =SUM(A2:A15) -> 4448.5 | B16: =SUM(B2:B15) -> 4857.98 | C16: =SUM(C2:C15) -> 4598.5 | D16: =SUM(D2:D15) -> 4278.81 | E16: =SUM(E2:E15) -> 850 | F16: =SUM(F2:F15) -> 3955 | G16: =SUM(G2:G15) -> 5408.5 | H16: =SUM(A16:G16)+I8 -> 46805.93 | I16: OASys Value
A17: 4448.5 | B17: 4857.98 | C17: 4598.5 | D17: 4278.81 | E17: 850 | F17: 3955 | G17: 5408.5 | H17: =SUM(A17:G17) -> 28397.29 | I17: Payroll Value
A18: =A16-A17 -> 0 | B18: =B16-B17 -> 0 | C18: =C16-C17 -> 0 | D18: =D16-D17 -> 0 | E18: =E16-E17 -> 0 | F18: =F16-F17 -> 0 | G18: =G16-G17 -> 0
A20: 44930 | B20: 44931 | C20: 44932 | D20: 44933 | E20: 44934 | F20: 44935 | G20: 44936 | I20: Registers
A21: 468.45 | B21: 220 | C21: 496.9 | D21: 220 | E21: 75 | F21: 826.9 | G21: 185 | I21: 4990.8
A22: 1333.8 | B22: 606.9 | C22: 405 | D22: 496.9 | E22: 75 | F22: 330 | G22: 468.45 | I22: 3690.2
A23: 1139.91 | B23: 1423.8 | C23: 490 | D23: 1353.8 | E23: 110 | F23: 813.8 | G23: 1588.8 | I23: 589.8
A24: 245 | B24: 1179.6 | C24: 681.9 | D24: 110 | E24: 110 | F24: 1525.43 | G24: 1470.12 | I24: 4797.26
A25: 110 | B25: 170 | C25: 1355.22 | D25: 220 | E25: 110 | F25: 235 | G25: 110 | I25: =3065+1050 -> 4115
A26: 297.45 | B26: 110 | C26: 350 | D26: 110 | F26: 445 | G26: 345 | I26: 1548.62
A27: 300 | B27: 455 | C27: 110 | D27: 1100.82 | F27: 110 | G27: 222.45 | I27: =SUM(I21:I26) -> 19731.68
A28: 447.75 | B28: 1275 | C28: 147.45 | D28: 350 | F28: 222.45 | G28: 185
A29: 150 | B29: 257.45 | C29: 240 | D29: 734.3 | F29: 250 | G29: 447.75
A30: 110 | B30: 305 | C30: 421.2 | F30: 824.3 | G30: 165
B31: 364.3 | C31: 150 | F31: 165
B32: 150 | C32: 110
B33: 110
A35: =SUM(A21:A34) -> 4602.36 | B35: =SUM(B21:B34) -> 6627.05 | C35: =SUM(C21:C34) -> 4957.67 | D35: =SUM(D21:D34) -> 4695.82 | E35: 480 | F35: =SUM(F21:F34) -> 5747.88 | G35: =SUM(G21:G34) -> 5187.57 | H35: =SUM(A35:G35)+I27 -> 52030.03 | I35: OASys Value
A36: 4602.36 | B36: 6627.05 | C36: 4957.67 | D36: 4695.82 | E36: 480 | F36: 5747.88 | G36: 5187.57 | H36: =SUM(A36:G36)+I27 -> 52030.03 | I36: Payroll Value
A37: =A35-A36 -> 0 | B37: =B35-B36 -> 0 | C37: =C35-C36 -> 0 | D37: =D35-D36 -> 0 | E37: =E35-E36 -> 0 | F37: =F35-F36 -> 0 | G37: =G35-G36 -> 0
A39: 44937 | B39: 44938 | C39: 44939 | D39: 44940 | E39: 44941 | F39: 44942 | G39: 44943 | I39: Registers
A40: 110 | B40: 440 | C40: 330 | D40: 220 | E40: 370 | F40: 550 | G40: 440 | I40: 4797.26
A41: 496.9 | B41: 138.45 | C41: 358.45 | D41: 386.9 | E41: 465 | F41: 330 | G41: 110 | I41: 4990.8
A42: 1548.8 | B42: 380 | C42: 1623.8 | D42: 380 | E42: 220 | F42: 1053.8 | G42: 1068.8 | I42: 5095
A43: 1100.22 | B43: 553.8 | C43: 1491.57 | D43: 805.35 | F43: 1570.95 | G43: 1650.33 | I43: 4943.92
A44: 170 | B44: 1395.12 | C44: 220 | D44: 185 | F44: 135 | G44: 185 | I44: 510.42
A45: 147.45 | B45: 185 | C45: 147.45 | D45: 370 | F45: 220 | G45: 270
...

Sheet February 2023
A1: 44958 | B1: 44959 | C1: 44960 | D1: 44961 | E1: 44962 | F1: 44963 | G1: 44964 | I1: Registers
A2: 440 | B2: 330 | C2: 681.9 | D2: 386.9 | E2: 150 | F2: 543.45 | G2: 440 | I2: 215.52 | Y2: 6495.9
A3: 75 | B3: 1103.8 | C3: 330 | D3: 185 | E3: 110 | F3: 578.45 | G3: 185 | I3: 4775 | Y3: 7075
A4: 923.8 | B4: 150 | C4: 873.45 | D4: 625 | E4: 110 | F4: 1016.9 | G4: 345 | I4: 4797.26
A5: 1695.64 | B5: 1355.43 | C5: 170 | D5: 85 | E5: 185 | F5: 1685.64 | G5: 858.8 | I5: 5238.82
A6: 60 | B6: 110 | C6: 1276.05 | D6: 660 | F6: 185 | G6: 1570.95 | I6: 3743.1
A7: 110 | B7: 295 | C7: 110 | D7: 110 | F7: 75 | G7: 195 | I7: 330
A8: 147.45 | B8: 475 | C8: 155 | D8: 1100.82 | F8: 100 | G8: 295
A9: 165 | B9: 147.45 | C9: 110 | D9: 230 | F9: 305 | G9: 147.45
A10: 606.2 | B10: 105 | C10: 147.45 | D10: 1714.18 | F10: 147.45 | G10: 90
A11: 165 | B11: 606.2 | C11: 195 | F11: 315 | G11: 256.2
A12: 300 | B12: 165 | C12: 209.65 | F12: 606.2 | G12: 180
B13: 320 | C13: 150 | F13: 165 | G13: 320
I14: =SUM(I2:I13) -> 19099.7
A18: =SUM(A2:A17) -> 4688.09 | B18: =SUM(B2:B17) -> 5162.88 | C18: =SUM(C2:C17) -> 4408.5 | D18: =SUM(D2:D17) -> 5096.9 | E18: =SUM(E2:E17) -> 555 | F18: =SUM(F2:F17) -> 5723.09 | G18: =SUM(G2:G17) -> 4883.4 | H18: =SUM(A18:G18)+I14 -> 49617.56 | I18: OASys Value
A19: 4688.09 | B19: 5162.88 | C19: 4408.5 | D19: 5096.9 | E19: 555 | F19: 5723.09 | G19: 4883.4 | H19: =SUM(A19:G19)+I14 -> 49617.56 | I19: Payroll Value
A20: =A18-A19 -> 0 | B20: =B18-B19 -> 0 | C20: =C18-C19 -> 0 | D20: =D18-D19 -> 0 | E20: =E18-E19 -> 0 | F20: =F18-F19 -> 0 | G20: =G18-G19 -> 0
A22: 44965 | B22: 44966 | C22: 44967 | D22: 44968 | E22: 44969 | F22: 44970 | G22: 44971 | I22: Registers | L22: 44965 | N22: 44966 | P22: 44967 | R22: 44968 | T22: 44969 | V22: 44970 | X22: 44971
A23: 75 | B23: 625 | C23: 1891.9 | D23: 1477.25 | E23: 150 | F23: 1938.8 | G23: 1788.8 | I23: 4797.26 | L23: Jobsheets | M23: Cash Vouchers | N23: Jobsheets | O23: Cash Vouchers | P23: Jobsheets | Q23: Cash Vouchers | R23: Jobsheets | S23: Cash Vouchers | T23: Jobsheets | U23: Cash Vouchers | V23: Jobsheets | W23: Cash Vouchers | X23: Jobsheets | Y23: Cash Vouchers
A24: 110 | B24: 358.45 | C24: 2054.02 | D24: 860 | E24: 240 | F24: 2693.09 | G24: 2172.88 | I24: 3743.1 | L24: 1530 | M24: 1620 | N24: 1200 | O24: 125 | P24: 4350 | Q24: 60 | R24: 2430 | S24: 257 | T24: 300 | V24: 4080 | W24: 42.5 | X24: 3900 | Y24: 60
A25: 405 | B25: 1310.35 | C25: 243.1 | D25: 592.75 | E25: 110 | F25: 771.2 | G25: 726.2 | I25: 4943.92 | L25: 1530 | M25: 65 | N25: 1320 | O25: 60 | P25: 1730 | Q25: 20 | R25: 880 | S25: 60 | T25: 1575 | V25: 1450 | W25: 24 | X25: 1920 | Y25: 30
A26: 930.35 | B26: 1383.81 | E26: 110 | I26: 4270 | L26: 1260 | M26: 30 | N26: 90 | P26: 290 | Q26: 37.5 | R26: 90 | T26: 120 | V26: 405 | X26: 650 | Y26: 125
A27: 138.45 | B27: 280 | I27: 350 | L27: 120 | M27: 80 | N27: 870 | P27: 210 | Q27: 189 | R27: 288 | T27: 72 | V27: 435 | X27: 264
A28: 1570.95 | B28: 222.45 | I28: 294.9 | L28: 110 | M28: 30 | N28: 120 | P28: 162 | R28: 24 | V28: 336 | X28: 24
A29: 265 | B29: 120 | I29: =SUM(I23:I28) -> 18399.18 | L29: 60 | N29: 210 | V29: 129 | Z29: =SUM(Z23:Z28) -> 0
A30: 185 | B30: 411.2 | L30: 120 | N30: 210
A31: 147.45 | B31: 150 | L31: 440 | N31: 210
A32: 155 | B32: 170 | L32: 30 | N32: 60
A33: 606.2 | L33: 60 | N33: 480
A34: 150 | L34: 450 | N34: 220
A35: 380 | L35: 186 | N35: 30
N36: 360
N37: 210
N38: 192
N39: 72
A40: =SUM(A23:A39) -> 5118.4 | B40: =SUM(B23:B39) -> 5031.26 | C40: =SUM(C23:C39) -> 4189.02 | D40: =SUM(D23:D39) -> 2930 | E40: =SUM(E23:E39) -> 610 | F40: =SUM(F23:F39) -> 5403.09 | G40: =SUM(G23:G39) -> 4687.88 | H40: =SUM(A40:G40)+I29 -> 46368.83 | I40: OASys Value | L40: =SUM(L24:L39) -> 5896 | M40: =SUM(M24:M39) -> 1825 | N40: =SUM(N24:N39) -> 5854 | O40: =SUM(O24:O39) -> 185 | P40: =SUM(P24:P39) -> 6742 | Q40: =SUM(Q24:Q39) -> 306.5 | R40: =SUM(R24:R39) -> 3712 | S40: =SUM(S24:S39) -> 317 | ... Y40: =SUM(Y24:Y39) -> 215 | Z40: =L41+N41+P41+R41+T41+V41+X41 -> 37864
A41: 5118.4 | B41: 5031.26 | C41: 4189.02 | D41: 2930 | E41: 610 | F41: 5403.09 | G41: 4687.88 | H41: =SUM(A41:G41)+I29 -> 46368.83 | I41: Payroll Value | K41: SubTotal | L41: 5896 | M41: 1825 | N41: 5854 | O41: 185 | P41: 6742 | Q41: 306.5 | R41: 3712 | S41: 317 | T41: 2067 | U41: 0 | V41: 6835 | W41: 66.5 | X41: 6758 | Y41: 215 | Z41: =M41+O41+Q41+S41+U41+W41+Y41 -> 2915
A42: =A40-A41 -> 0 | B42: =B40-B41 -> 0 | C42: =C40-C41 -> 0 | D42: =D40-D41 -> 0 | E42: =E40-E41 -> 0 | F42: =F40-F41 -> 0 | G42: =G40-G41 -> 0 | K42: Difference | L42: =L40-L41 -> 0 | M42: =M40-M41 -> 0 | N42: =N40-N41 -> 0 | O42: =O40-O41 -> 0 | P42: =P40-P41 -> 0 | Q42: =Q40-Q41 -> 0 | R42: =R40-R41 -> 0 | S42: =S40-S41 -> 0 | ... Y42: =Y40-Y41 -> 0
A44: 44972 | B44: 44973 | C44: 44974 | D44: 44975 | E44: 44976 | F44: 44977 | G44: 44978 | I44: Registers | L44: 44972 | N44: 44973 | P44: 44974 | R44: 44975 | T44: 44976 | V44: 44977 | X44: 44978
A45: 1653.8 | B45: 1555.35 | C45: 885 | D45: 1455 | E45: 540 | F45: 1815.35 | G45: 1873.8 | I45: 3743.1 | L45: Jobsheets | M45: Cash Vouchers | N45: Jobsheets | O45: Cash Vouchers | P45: Jobsheets | Q45: Cash Vouchers | R45: Jobsheets | S45: Cash Vouchers | T45: Jobsheets | U45: Cash Vouchers | V45: Jobsheets | W45: Cash Vouchers | X45: Jobsheets | Y45: Cash Vouchers
...

Sheet March 2023
A1: 44986 | B1: 44987 | C1: 44988 | D1: 44989 | E1: 44990 | F1: 44991 | G1: 44992 | I1: Registers | L1: 44986 | N1: 44987 | P1: 44988 | R1: 44989 | T1: 44990 | V1: 44991 | X1: 44992
A2: 1596.9 | B2: 1530.35 | C2: 2186.9 | D2: 1508.8 | E2: 370 | G2: 1828.8 | I2: 700 | L2: Jobsheets | M2: Cash Vouchers | N2: Jobsheets | O2: Cash Vouchers | P2: Jobsheets | Q2: Cash Vouchers | R2: Jobsheets | S2: Cash Vouchers | T2: Jobsheets | U2: Cash Vouchers | V2: Jobsheets | W2: Cash Vouchers | X2: Jobsheets | Y2: Cash Vouchers
A3: 2108.19 | B3: 3264.02 | C3: 1809.02 | D3: 2060.82 | E3: 110 | G3: 1254.6 | I3: 510.42 | L3: 4350 | M3: 60 | N3: 4080 | O3: 220 | P3: 3930 | Q3: 80 | R3: 2820 | S3: 65 | T3: 120 | V3: 4440 | W3: 372 | X3: 4020 | Y3: 125
A4: 983.1 | B4: 609.65 | C4: 313.1 | D4: 511.2 | G4: 882.45 | I4: 4455 | L4: 1060 | M4: 237.5 | N4: 2570 | O4: 120 | P4: 1890 | Q4: 180 | R4: 1170 | T4: 360 | V4: 2190 | W4: 290 | X4: 1485 | Y4: 24
G5: 256.2 | I5: 4797.26 | L5: 540 | N5: 460 | P5: 980 | R5: 90 | T5: 120 | V5: 800 | X5: 275
F6: 1518.8 | G6: 165 | I6: 4943.92 | L6: 72 | N6: 222 | P6: 72 | R6: 395 | T6: 72 | V6: 300 | X6: 228
F7: 2072.88 | I7: 3924.6 | L7: 24 | P7: 90 | R7: 24 | V7: 90 | X7: 60
F8: 1026.2 | I8: =SUM(I2:I7) -> 19331.2 | L8: 90 | Z8: =SUM(Z2:Z7) -> 0
A16: =SUM(A2:A15) -> 4688.19 | B16: =SUM(B2:B15) -> 5404.02 | C16: =SUM(C2:C15) -> 4309.02 | D16: =SUM(D2:D15) -> 4080.82 | E16: =SUM(E2:E15) -> 480 | F16: =SUM(F2:F15) -> 4617.88 | G16: =SUM(G2:G15) -> 4387.05 | H16: =SUM(A16:G16)+I8 -> 47298.18 | I16: OASys Value | L16: =SUM(L3:L15) -> 6136 | M16: =SUM(M3:M15) -> 297.5 | N16: =SUM(N3:N15) -> 7332 | O16: =SUM(O3:O15) -> 340 | P16: =SUM(P3:P15) -> 6962 | Q16: =SUM(Q3:Q15) -> 260 | R16: =SUM(R3:R15) -> 4499 | S16: =SUM(S3:S15) -> 65 | ... Y16: =SUM(Y3:Y15) -> 149 | Z16: =L17+N17+P17+R17+T17+V17+X17 -> 39489
A17: 4688.19 | B17: 5404.02 | C17: 4309.02 | D17: 4080.82 | E17: 480 | F17: 4617.88 | G17: 4387.05 | H17: =SUM(A17:G17)+I8 -> 47298.18 | I17: Payroll Value | L17: 6136 | M17: 297.5 | N17: 7332 | O17: 340 | P17: 6962 | Q17: 260 | R17: 4499 | S17: 65 | T17: 672 | U17: 0 | V17: 7820 | W17: 662 | X17: 6068 | Y17: 149 | Z17: =M17+O17+Q17+S17+U17+W17+Y17 -> 1773.5
A18: =A16-A17 -> 0 | B18: =B16-B17 -> 0 | C18: =C16-C17 -> 0 | D18: =D16-D17 -> 0 | E18: =E16-E17 -> 0 | F18: =F16-F17 -> 0 | G18: =G16-G17 -> 0 | L18: =L16-L17 -> 0 | M18: =M16-M17 -> 0 | N18: =N16-N17 -> 0 | O18: =O16-O17 -> 0 | P18: =P16-P17 -> 0 | Q18: =Q16-Q17 -> 0 | R18: =R16-R17 -> 0 | S18: =S16-S17 -> 0 | ... Y18: =Y16-Y17 -> 0
A20: 44993 | B20: 44994 | C20: 44995 | D20: 44996 | E20: 44997 | F20: 44998 | G20: 44999 | I20: Registers | L20: 44993 | N20: 44994 | P20: 44995 | R20: 44996 | T20: 44997 | V20: 44998 | X20: 44999
A21: 1668.8 | B21: 1637.25 | C21: 1275 | D21: 1633.8 | E21: 185 | F21: 936.9 | G21: 1338.45 | I21: 5238.82 | L21: Jobsheets | M21: Cash Vouchers | N21: Jobsheets | O21: Cash Vouchers | P21: Jobsheets | Q21: Cash Vouchers | R21: Jobsheets | S21: Cash Vouchers | T21: Jobsheets | U21: Cash Vouchers | V21: Jobsheets | W21: Cash Vouchers | X21: Jobsheets | Y21: Cash Vouchers
A22: 1792.88 | B22: 1917.98 | C22: 635.35 | D22: 1825.82 | E22: 220 | F22: 3182.26 | G22: 2242.05 | I22: 294.9 | L22: 4380 | M22: 65 | N22: 4080 | O22: 237.9 | P22: 3990 | Q22: 107 | R22: 2770 | S22: 120 | T22: 60 | U22: 0 | V22: 2980 | W22: 57.5 | X22: 2430 | Y22: 125
A23: 406.2 | B23: 822.75 | C23: 1838.5 | D23: 346.2 | E23: 110 | F23: 165 | G23: 341.55 | I23: 4820.7 | L23: 1050 | M23: 1980 | N23: 1410 | O23: 65 | P23: 60 | Q23: 120 | R23: 1320 | S23: 12 | T23: 180 | V23: 1510 | W23: 242.2 | X23: 1700 | Y23: 900
C24: 509.65 | F24: 223.1 | I24: 1750 | L24: 610 | N24: 710 | P24: 1760 | Q24: 130 | R24: 228 | S24: 57.5 | T24: 60 | V24: 1050 | X24: 60
I25: 4797.26 | L25: 72 | N25: 228 | P25: 340 | S25: 65 | T25: 72 | V25: 252 | X25: 660
I26: 3950 | L26: 90 | P26: 72 | V26: 90 | X26: 300
P27: 72 | X27: 48 | Z27: =SUM(Z21:Z26) -> 0
I28: =SUM(I21:I27) -> 20851.68
A35: =SUM(A21:A34) -> 3867.88 | B35: =SUM(B21:B34) -> 4377.98 | C35: =SUM(C21:C34) -> 4258.5 | D35: =SUM(D21:D34) -> 3805.82 | E35: =SUM(E21:E34) -> 515 | F35: =SUM(F21:F34) -> 4507.26 | G35: =SUM(G21:G34) -> 3922.05 | H35: =SUM(A35:G35)+I28 -> 46106.17 | I35: OASys Value | L35: =SUM(L22:L34) -> 6202 | M35: =SUM(M22:M34) -> 2045 | N35: =SUM(N22:N34) -> 6428 | O35: =SUM(O22:O34) -> 302.9 | P35: =SUM(P22:P34) -> 6294 | Q35: =SUM(Q22:Q34) -> 357 | R35: =SUM(R22:R34) -> 4318 | S35: =SUM(S22:S34) -> 254.5 | ... Y35: =SUM(Y22:Y34) -> 1025 | Z35: =L36+N36+P36+R36+T36+V36+X36 -> 34694
A36: 3867.88 | B36: 4377.98 | C36: 4258.5 | D36: 3805.82 | E36: 515 | F36: 4507.26 | G36: 3922.05 | H36: =SUM(A36:G36)+I28 -> 46106.17 | I36: Payroll Value | L36: 6202 | M36: 2045 | N36: 6428 | O36: 302.9 | P36: 6294 | Q36: 357 | R36: 4318 | S36: 254.5 | T36: 372 | U36: 0 | V36: 5882 | W36: 299.7 | X36: 5198 | Y36: 1025 | Z36: =M36+O36+Q36+S36+U36+W36+Y36 -> 4284.1
A37: =A35-A36 -> 0 | B37: =B35-B36 -> 0 | C37: =C35-C36 -> 0 | D37: =D35-D36 -> 0 | E37: =E35-E36 -> 0 | F37: =F35-F36 -> 0 | G37: =G35-G36 -> 0 | L37: =L35-L36 -> 0 | M37: =M35-M36 -> 0 | N37: =N35-N36 -> 0 | O37: =O35-O36 -> 0 | P37: =P35-P36 -> 0 | Q37: =Q35-Q36 -> 0 | R37: =R35-R36 -> 0 | S37: =S35-S36 -> 0 | ... Y37: =Y35-Y36 -> 0
A39: 45000 | B39: 45001 | C39: 45002 | D39: 45003 | E39: 45004 | F39: 45005 | G39: 45006 | I39: Registers | L39: 45000 | N39: 45001 | P39: 45002 | R39: 45003 | T39: 45004 | V39: 45005 | X39: 45006
A40: 1740.35 | B40: 1575.35 | C40: 1590.35 | D40: 1243.45 | E40: 195 | F40: 1225.35 | G40: 1075.35 | I40: 5135 | L40: Jobsheets | M40: Cash Vouchers | N40: Jobsheets | O40: Cash Vouchers | P40: Jobsheets | Q40: Cash Vouchers | R40: Jobsheets | S40: Cash Vouchers | T40: Jobsheets | U40: Cash Vouchers | V40: Jobsheets | W40: Cash Vouchers | X40: Jobsheets | Y40: Cash Vouchers
A41: 1868.19 | B41: 2682.57 | C41: 2237.88 | D41: 540 | E41: 220 | F41: 2558.19 | G41: 570 | I41: 4605.18 | L41: 2420 | M41: 31.5 | N41: 2370 | O41: 57.5 | P41: 2550 | Q41: 94 | R41: 1860 | S41: 3960 | T41: 60 | V41: 2700 | W41: 120 | X41: 2710 | Y41: 65
A42: 1009.65 | B42: 894.65 | C42: 579.65 | D42: 431.55 | E42: 110 | F42: 679.65 | G42: 165 | I42: 5238.82 | L42: 1770 | M42: 65 | N42: 1230 | O42: 182.5 | P42: 2165 | R42: 1100 | S42: 47.5 | T42: 180 | V42: 2120 | W42: 50 | X42: 1290 | Y42: 20
G43: 209.65 | I43: 1315.74 | L43: 780 | M43: 42 | N43: 990 | P43: 705 | R43: 300 | T43: 120 | V43: 710 | W43: 391.9 | X43: 700 | Y43: 60
I44: 5166.28 | L44: 144 | N44: 300 | P44: 144 | R44: 306 | T44: 72 | V44: 744 | X44: 300
I45: 1050 | L45: 66 | N45: 26 | P45: 90 | R45: 26 | V45: 114
I46: =SUM(I40:I45) -> 22511.02 | Z46: =SUM(Z40:Z45) -> 0
A54: =SUM(A40:A53) -> 4618.19 | B54: =SUM(B40:B53) -> 5152.57 | C54: =SUM(C40:C53) -> 4407.88 | D54: =SUM(D40:D53) -> 2215 | E54: =SUM(E40:E53) -> 525 | F54: =SUM(F40:F53) -> 4463.19 | G54: =SUM(G40:G53) -> 2020 | H54: =SUM(A54:G54)+I46 -> 45912.85 | I54: OASys Value | L54: =SUM(L41:L53) -> 5180 | M54: =SUM(M41:M53) -> 138.5 | N54: =SUM(N41:N53) -> 4916 | O54: =SUM(O41:O53) -> 240 | P54: =SUM(P41:P53) -> 5654 | Q54: =SUM(Q41:Q53) -> 94 | R54: =SUM(R41:R53) -> 3592 | S54: =SUM(S41:S53) -> 4007.5 | ... Y54: =SUM(Y41:Y53) -> 145 | Z54: =L55+N55+P55+R55+T55+V55+X55 -> 31162
A55: 4618.19 | B55: 5152.57 | C55: 4407.88 | D55: 2215 | E55: 525 | F55: 4463.19 | G55: 2020 | H55: =SUM(A55:G55)+I46 -> 45912.85 | I55: Payroll Value | L55: 5180 | M55: 138.5 | N55: 4916 | O55: 240 | P55: 5654 | Q55: 94 | R55: 3592 | S55: 4007.5 | T55: 432 | U55: 0 | V55: 6388 | W55: 561.9 | X55: 5000 | Y55: 145 | Z55: =M55+O55+Q55+S55+U55+W55+Y55 -> 5186.9
A56: =A54-A55 -> 0 | B56: =B54-B55 -> 0 | C56: =C54-C55 -> 0 | D56: =D54-D55 -> 0 | E56: =E54-E55 -> 0 | F56: =F54-F55 -> 0 | G56: =G54-G55 -> 0 | L56: =L54-L55 -> 0 | M56: =M54-M55 -> 0 | N56: =N54-N55 -> 0 | O56: =O54-O55 -> 0 | P56: =P54-P55 -> 0 | Q56: =Q54-Q55 -> 0 | R56: =R54-R55 -> 0 | S56: =S54-S55 -> 0 | ... Y56: =Y54-Y55 -> 0
A58: 45007 | B58: 45008 | C58: 45009 | D58: 45010 | E58: 45011 | F58: 45012 | G58: 45013 | I58: Registers | L58: 45007 | M58: 45007 | N58: 45008 | P58: 45009 | R58: 45010 | T58: 45011 | V58: 45012 | X58: 45013
A59: 1373.8 | B59: 1445.35 | C59: 1696.9 | D59: 940 | E59: 110 | F59: 1555.35 | G59: 1448.8 | I59: 4571.16 | L59: Jobsheets | M59: Cash Vouchers | N59: Jobsheets | O59: Cash Vouchers | P59: Jobsheets | Q59: Cash Vouchers | R59: Jobsheets | S59: Cash Vouchers | T59: Jobsheets | U59: Cash Vouchers | V59: Jobsheets | W59: Cash Vouchers | X59: Jobsheets | Y59: Cash Vouchers
A60: 1787.67 | B60: 110 | C60: 2018.19 | D60: 3706.39 | E60: 850 | F60: 2128.5 | G60: 1400.22 | I60: 294.9 | L60: 2700 | M60: 50 | N60: 2220 | O60: 110 | P60: 2370 | Q60: 65 | R60: 1980 | S60: 45 | T60: 120 | U60: 0 | V60: 2590 | W60: 117.5 | X60: 2490 | Y60: 2010
A61: 951.2 | B61: 2273.19 | C61: 508.1 | D61: 220 | F61: 644.65 | G61: 767.45 | I61: 4797.26 | L61: 1710 | N61: 1615 | P61: 1915 | Q61: 30 | R61: 1670 | S61: 60 | T61: 1200 | V61: 1970 | W61: 74 | X61: 1970 | Y61: 57.5
B62: 944.65 | G62: 421.2 | I62: 5640 | L62: 970 | N62: 1045 | P62: 60 | R62: 440 | T62: 210 | V62: 660 | X62: 610
G63: 150 | I63: 3690.2 | L63: 144 | N63: 300 | P63: 785 | R63: 198 | T63: 72 | V63: 300 | X63: 300
...

Sheet April 2023
A1: 45014 | B1: 45015 | C1: 45016 | D1: 45017 | E1: 45018 | F1: 45019 | G1: 45020 | I1: Registers | L1: 45014 | M1: 45014 | N1: 45015 | P1: 45016 | R1: 45017 | T1: 45018 | V1: 45019 | X1: 45020
L2: Jobsheets | M2: Cash Vouchers | N2: Jobsheets | O2: Cash Vouchers | P2: Jobsheets | Q2: Cash Vouchers | R2: Jobsheets | S2: Cash Vouchers | T2: Jobsheets | U2: Cash Vouchers | V2: Jobsheets | W2: Cash Vouchers | X2: Jobsheets | Y2: Cash Vouchers
L3: 2490 | M3: 1620 | N3: 2530 | O3: 108.5 | P3: 2490 | Q3: 1800 | R3: 1960 | S3: 40 | T3: 120 | U3: 0 | V3: 2700 | W3: 290 | X3: 2520 | Y3: 480
L4: 1660 | M4: 42.5 | N4: 1190 | P4: 1950 | Q4: 65 | R4: 760 | T4: 120 | V4: 1790 | X4: 1910 | Y4: 57.5
L5: 570 | N5: 650 | P5: 610 | Q5: 99.9 | R5: 300 | T5: 150 | V5: 1100 | X5: 880 | Y5: 38.9
L6: 144 | N6: 300 | P6: 144 | Q6: 372 | R6: 204 | T6: 72 | V6: 287 | X6: 288
L7: 90 | P7: 72 | V7: 90 | X7: 24
I8: =SUM(I2:I7) -> 0 | Z8: =SUM(Z2:Z7) -> 0
A16: =SUM(A2:A15) -> 0 | B16: =SUM(B2:B15) -> 0 | C16: =SUM(C2:C15) -> 0 | D16: =SUM(D2:D15) -> 0 | E16: =SUM(E2:E15) -> 0 | F16: =SUM(F2:F15) -> 0 | G16: =SUM(G2:G15) -> 0 | H16: =SUM(A16:G16)+I8 -> 0 | I16: OASys Value | L16: =SUM(L3:L15) -> 4954 | M16: =SUM(M3:M15) -> 1662.5 | N16: =SUM(N3:N15) -> 4670 | O16: =SUM(O3:O15) -> 108.5 | P16: =SUM(P3:P15) -> 5266 | Q16: =SUM(Q3:Q15) -> 2336.9 | R16: =SUM(R3:R15) -> 3224 | S16: =SUM(S3:S15) -> 40 | ... Y16: =SUM(Y3:Y15) -> 576.4 | Z16: =L16+N16+P16+R16+T16+V16+X16 -> 30165
H17: =SUM(A17:G17) -> 0 | I17: Payroll Value | L17: 4954 | M17: 1662.5 | N17: 4670 | O17: 108.5 | P17: 5266 | Q17: 2336.9 | R17: 3224 | S17: 40 | T17: 462 | U17: 0 | V17: 5967 | W17: 290 | X17: 5622 | Y17: 576.4 | Z17: =M17+O17+Q17+S17+U17+W17+Y17 -> 5014.3
A18: =A16-A17 -> 0 | B18: =B16-B17 -> 0 | C18: =C16-C17 -> 0 | D18: =D16-D17 -> 0 | E18: =E16-E17 -> 0 | F18: =F16-F17 -> 0 | G18: =G16-G17 -> 0 | L18: =L16-L17 -> 0 | M18: =M16-M17 -> 0 | N18: =N16-N17 -> 0 | O18: =O16-O17 -> 0 | P18: =P16-P17 -> 0 | Q18: =Q16-Q17 -> 0 | R18: =R16-R17 -> 0 | S18: =S16-S17 -> 0 | ... Y18: =Y16-Y17 -> 0
A20: 45021 | B20: 45022 | C20: 45023 | D20: 45024 | E20: 45025 | F20: 45026 | G20: 45027 | I20: Registers | L20: 45021 | N20: 45022 | P20: 45023 | R20: 45024 | T20: 45025 | V20: 45026 | X20: 45027
A21: 1633.8 | B21: 1485.35 | C21: 1720.35 | D21: 1433.45 | E21: 110 | F21: 1925.35 | G21: 1378.8 | I21: 5828.62 | L21: Jobsheets | M21: Cash Vouchers | N21: Jobsheets | O21: Cash Vouchers | P21: Jobsheets | Q21: Cash Vouchers | R21: Jobsheets | S21: Cash Vouchers | T21: Jobsheets | U21: Cash Vouchers | V21: Jobsheets | W21: Cash Vouchers | X21: Jobsheets | Y21: Cash Vouchers
A22: 2072.05 | B22: 2547.57 | C22: 375 | D22: 2998.38 | E22: 185 | F22: 710 | G22: 2177.05 | I22: 5535.3 | L22: 2550 | M22: 60 | N22: 2460 | O22: 57.5 | P22: 2460 | Q22: 1380 | R22: 1680 | S22: 1620 | T22: 60 | U22: 0 | V22: 2320 | W22: 50 | X22: 2510 | Y22: 840
A23: 731.2 | B23: 764.65 | C23: 669.65 | D23: 156.55 | E23: 75 | F23: 719.65 | G23: 561.2 | I23: 4264.89 | L23: 1850 | M23: 60 | N23: 1280 | O23: 200 | P23: 1455 | Q23: 65 | R23: 1470 | S23: 45 | T23: 150 | V23: 1730 | X23: 1665 | Y23: 372
I24: 2336.58 | L24: 120 | N24: 500 | O24: 200 | P24: 555 | R24: 430 | T24: 48 | V24: 720 | X24: 60 | Y24: 50
I25: 3785 | L25: 1120 | N25: 300 | P25: 72 | R25: 348 | V25: 475 | X25: 535
I26: 1320 | L26: 222 | N26: 26 | P26: 72 | R26: 24 | X26: 144
I27: =SUM(I21:I26) -> 23070.39 | L27: 90 | X27: 24 | Z27: =SUM(Z21:Z26) -> 0
A35: =SUM(A21:A34) -> 4437.05 | B35: =SUM(B21:B34) -> 4797.57 | C35: =SUM(C21:C34) -> 2765 | D35: =SUM(D21:D34) -> 4588.38 | E35: =SUM(E21:E34) -> 370 | F35: =SUM(F21:F34) -> 3355 | G35: =SUM(G21:G34) -> 4117.05 | H35: =SUM(A35:G35)+I27 -> 47500.44 | I35: OASys Value | L35: =SUM(L22:L34) -> 5952 | M35: =SUM(M22:M34) -> 120 | N35: =SUM(N22:N34) -> 4566 | O35: =SUM(O22:O34) -> 457.5 | P35: =SUM(P22:P34) -> 4614 | Q35: =SUM(Q22:Q34) -> 1445 | R35: =SUM(R22:R34) -> 3952 | S35: =SUM(S22:S34) -> 1665 | ... Y35: =SUM(Y22:Y34) -> 1262 | Z35: =L35+N35+P35+R35+T35+V35+X35 -> 29525
A36: 4437.05 | B36: 4797.57 | C36: 2765 | D36: 4588.38 | E36: 370 | F36: 3355 | G36: 4117.05 | H36: =SUM(A36:G36)+I27 -> 47500.44 | I36: Payroll Value | L36: 5952 | M36: 120 | N36: 4566 | O36: 457.5 | P36: 4614 | Q36: 1445 | R36: 3952 | S36: 1665 | T36: 258 | U36: 0 | V36: 5245 | W36: 50 | X36: 4938 | Y36: 1262 | Z36: =M36+O36+Q36+S36+U36+W36+Y36 -> 4999.5
A37: =A35-A36 -> 0 | B37: =B35-B36 -> 0 | C37: =C35-C36 -> 0 | D37: =D35-D36 -> 0 | E37: =E35-E36 -> 0 | F37: =F35-F36 -> 0 | G37: =G35-G36 -> 0 | L37: =L35-L36 -> 0 | M37: =M35-M36 -> 0 | N37: =N35-N36 -> 0 | O37: =O35-O36 -> 0 | P37: =P35-P36 -> 0 | Q37: =Q35-Q36 -> 0 | R37: =R35-R36 -> 0 | S37: =S35-S36 -> 0 | ... Y37: =Y35-Y36 -> 0
A39: 45028 | B39: 45029 | C39: 45030 | D39: 45031 | E39: 45032 | F39: 45033 | G39: 45034 | I39: Registers | L39: 45028 | N39: 45029 | P39: 45030 | R39: 45031 | T39: 45032 | V39: 45033 | X39: 45034
A40: 1420.35 | B40: 1131.9 | C40: 1690.35 | D40: 948.45 | E40: 295 | F40: 976.9 | G40: 1698.8 | I40: 4943.92 | L40: Jobsheets | M40: Cash Vouchers | N40: Jobsheets | O40: Cash Vouchers | P40: Jobsheets | Q40: Cash Vouchers | R40: Jobsheets | S40: Cash Vouchers | T40: Jobsheets | U40: Cash Vouchers | V40: Jobsheets | W40: Cash Vouchers | X40: Jobsheets | Y40: Cash Vouchers
A41: 2162.05 | B41: 2292.98 | C41: 1747.36 | D41: 3330.44 | F41: 110 | G41: 2392.26 | I41: 4797.26 | L41: 2640 | M41: 540 | N41: 2580 | O41: 60 | P41: 2490 | Q41: 77 | R41: 2070 | S41: 1800 | T41: 330 | V41: 2790 | W41: 741.3 | X41: 2400 | Y41: 1920
A42: 1004.65 | B42: 1003.1 | C42: 1019.65 | D42: 431.55 | F42: 2247.57 | G42: 546.2 | I42: 4610 | L42: 1860 | M42: 50 | N42: 1340 | O42: 50 | P42: 2490 | Q42: 30 | R42: 1230 | S42: 57.5 | T42: 72 | V42: 2350 | X42: 1870 | Y42: 235
F43: 868.1 | I43: 4571.16 | L43: 760 | M43: 99.9 | N43: 830 | P43: 770 | R43: 300 | V43: 1140 | X43: 430
I44: 725.94 | L44: 352 | N44: 300 | P44: 144 | R44: 252 | V44: 300 | X44: 300
I45: 700 | L45: 78 | N45: 26 | P45: 78 | V45: 103 | X45: 24
I46: =SUM(I40:I45) -> 20348.28 | Z46: =SUM(Z40:Z45) -> 0
A54: =SUM(A40:A53) -> 4587.05 | B54: =SUM(B40:B53) -> 4427.98 | C54: =SUM(C40:C53) -> 4457.36 | D54: =SUM(D40:D53) -> 4710.44 | E54: =SUM(E40:E53) -> 295 | F54: =SUM(F40:F53) -> 4202.57 | G54: =SUM(G40:G53) -> 4637.26 | H54: =SUM(A54:G54)+I46 -> 47665.94 | I54: OASys Value | L54: =SUM(L41:L53) -> 5690 | M54: =SUM(M41:M53) -> 689.9 | N54: =SUM(N41:N53) -> 5076 | O54: =SUM(O41:O53) -> 110 | P54: =SUM(P41:P53) -> 5972 | Q54: =SUM(Q41:Q53) -> 107 | R54: =SUM(R41:R53) -> 3852 | S54: =SUM(S41:S53) -> 1857.5 | ... Y54: =SUM(Y41:Y53) -> 2155 | Z54: =L55+N55+P55+R55+T55+V55+X55 -> 32699
A55: 4587.05 | B55: 4427.98 | C55: 4457.36 | D55: 4710.44 | E55: 295 | F55: 4202.57 | G55: 4637.26 | H55: =SUM(A55:G55)+I46 -> 47665.94 | I55: Payroll Value | L55: 5690 | M55: 689.9 | N55: 5076 | O55: 110 | P55: 5972 | Q55: 107 | R55: 3852 | S55: 1857.5 | T55: 402 | V55: 6683 | W55: 741.3 | X55: 5024 | Y55: 2155 | Z55: =M55+O55+Q55+S55+U55+W55+Y55 -> 5660.7
A56: =A54-A55 -> 0 | B56: =B54-B55 -> 0 | C56: =C54-C55 -> 0 | D56: =D54-D55 -> 0 | E56: =E54-E55 -> 0 | F56: =F54-F55 -> 0 | G56: =G54-G55 -> 0 | L56: =L54-L55 -> 0 | M56: =M54-M55 -> 0 | N56: =N54-N55 -> 0 | O56: =O54-O55 -> 0 | P56: =P54-P55 -> 0 | Q56: =Q54-Q55 -> 0 | R56: =R54-R55 -> 0 | S56: =S54-S55 -> 0 | ... Y56: =Y54-Y55 -> 0
A58: 45035 | B58: 45036 | C58: 45037 | D58: 45038 | E58: 45039 | F58: 45040 | G58: 45041 | I58: Registers | L58: 45035 | N58: 45036 | P58: 45037 | R58: 45038 | T58: 45039 | V58: 45040 | X58: 45041
A59: 1635.35 | B59: 1300.35 | C59: 1236.9 | D59: 940 | E59: 185 | F59: 951.9 | G59: 1293.8 | I59: 215.52 | L59: Jobsheets | M59: Cash Vouchers | N59: Jobsheets | O59: Cash Vouchers | P59: Jobsheets | Q59: Cash Vouchers | R59: Jobsheets | S59: Cash Vouchers | T59: Jobsheets | U59: Cash Vouchers | V59: Jobsheets | W59: Cash Vouchers | X59: Jobsheets | Y59: Cash Vouchers
A60: 2077.88 | B60: 2352.57 | C60: 138.45 | D60: 138.45 | F60: 248.45 | G60: 2187.05 | I60: 1050 | L60: 2530 | M60: 60 | N60: 2620 | O60: 57.5 | P60: 2740 | Q60: 65 | R60: 1920 | S60: 1440 | T60: 60 | V60: 2890 | W60: 372 | X60: 2610 | Y60: 1320
A61: 484.65 | B61: 469.65 | C61: 2067.57 | D61: 138.45 | F61: 1945.12 | G61: 456.2 | I61: 4630 | L61: 1985 | M61: 65 | N61: 1900 | O61: 60 | P61: 2285 | Q61: 60 | R61: 1300 | S61: 110 | T61: 210 | V61: 2245 | W61: 57.5 | X61: 2110 | Y61: 57.5
C62: 374.65 | D62: 3535.73 | F62: 287.45 | I62: 4797.26 | L62: 775 | M62: 189.9 | N62: 60 | P62: 725 | R62: 170 | T62: 210 | V62: 60 | W62: 60 | X62: 780
D63: 458.1 | F63: 614.65 | I63: 4820.7 | L63: 222 | N63: 780 | P63: 258 | R63: 228 | T63: 72 | V63: 615 | X63: 300
I64: 4943.92 | L64: 114 | N64: 300 | V64: 300 | X64: 72
...

Sheet May 2023
A1: 45049 | B1: 45050 | C1: 45051 | D1: 45052 | E1: 45053 | F1: 45054 | G1: 45055 | I1: Registers | K1: 45049 | M1: 45050 | O1: 45051 | Q1: 45052 | S1: 45053 | U1: 45054 | W1: 45055
A2: 1370.35 | B2: 805 | C2: 1161.9 | D2: 976.9 | E2: 110 | F2: 1403.8 | G2: 976.9 | I2: 3690.2 | K2: Jobsheets | L2: Cash Vouchers | M2: Jobsheets | N2: Cash Vouchers | O2: Jobsheets | P2: Cash Vouchers | Q2: Jobsheets | R2: Cash Vouchers | S2: Jobsheets | T2: Cash Vouchers | U2: Jobsheets | V2: Cash Vouchers | W2: Jobsheets | X2: Cash Vouchers
A3: 1803.19 | B3: 248.45 | C3: 1913.19 | D3: 2248.38 | F3: 1972.36 | G3: 2302.05 | I3: 1253.72 | K3: 2700 | L3: 290 | M3: 2670 | N3: 248 | O3: 2770 | P3: 65 | Q3: 1920 | R3: 60 | S3: 540 | U3: 2710 | V3: 50 | W3: 2460 | X3: 60
A4: 759.65 | B4: 2053.19 | C4: 348.1 | D4: 808.1 | F4: 636.2 | G4: 353.1 | I4: 4616.49 | K4: 1810 | L4: 634 | M4: 1805 | N4: 372 | O4: 1985 | Q4: 1270 | R4: 50 | S4: 84 | U4: 2520 | W4: 180 | X4: 67.5
B5: 536.55 | I5: 4980 | K5: 760 | L5: 1410 | M5: 1385 | O5: 445 | Q5: 240 | U5: 560 | W5: 2640 | X5: 24
I6: 4797.26 | K6: 222 | M6: 288 | O6: 144 | Q6: 228 | U6: 372 | W6: 840
I7: 350 | M7: 85 | Q7: 72 | U7: 24 | W7: 516
I8: 430.3 | W8: 96 | Y8: =SUM(Y2:Y7) -> 0
I10: =SUM(I2:I9) -> 20117.97
A16: =SUM(A2:A15) -> 3933.19 | B16: =SUM(B2:B15) -> 3643.19 | C16: =SUM(C2:C15) -> 3423.19 | D16: =SUM(D2:D15) -> 4033.38 | E16: =SUM(E2:E15) -> 110 | F16: =SUM(F2:F15) -> 4012.36 | G16: =SUM(G2:G15) -> 3632.05 | H16: =SUM(A16:G16)+I10 -> 42905.33 | I16: OASys Value | K16: =SUM(K3:K15) -> 5492 | L16: =SUM(L3:L15) -> 2334 | M16: =SUM(M3:M15) -> 6233 | N16: =SUM(N3:N15) -> 620 | O16: =SUM(O3:O15) -> 5344 | P16: =SUM(P3:P15) -> 65 | Q16: =SUM(Q3:Q15) -> 3730 | R16: =SUM(R3:R15) -> 110 | ... X16: =SUM(X3:X15) -> 151.5 | Y16: =K17+M17+O17+Q17+S17+U17+W17 -> 34341
A17: 3933.19 | B17: 3643.19 | C17: 3423.19 | D17: 4033.38 | E17: 110 | F17: 4012.36 | G17: 3632.05 | H17: =SUM(A17:G17)+I10 -> 42905.33 | I17: Payroll Value | K17: 5492 | L17: 2334 | M17: 6233 | N17: 620 | O17: 5344 | P17: 65 | Q17: 3730 | R17: 110 | S17: 624 | T17: 0 | U17: 6186 | V17: 50 | W17: 6732 | X17: 151.5 | Y17: =L17+N17+P17+R17+T17+V17+X17 -> 3330.5
A18: =A16-A17 -> 0 | B18: =B16-B17 -> 0 | C18: =C16-C17 -> 0 | D18: =D16-D17 -> 0 | E18: =E16-E17 -> 0 | F18: =F16-F17 -> 0 | G18: =G16-G17 -> 0 | K18: =K16-K17 -> 0 | L18: =L16-L17 -> 0 | M18: =M16-M17 -> 0 | N18: =N16-N17 -> 0 | O18: =O16-O17 -> 0 | P18: =P16-P17 -> 0 | Q18: =Q16-Q17 -> 0 | R18: =R16-R17 -> 0 | ... X18: =X16-X17 -> 0
A20: 45056 | B20: 45057 | C20: 45058 | D20: 45059 | E20: 45060 | F20: 45061 | G20: 45062 | I20: Registers | K20: 45056 | M20: 45057 | O20: 45058 | Q20: 45059 | S20: 45060 | U20: 45061 | W20: 45062
A21: 1126.9 | B21: 748.45 | C21: 1340.35 | D21: 1016.9 | E21: 185 | F21: 890 | G21: 1253.8 | I21: 4866.03 | K21: Jobsheets | L21: Cash Vouchers | M21: Jobsheets | N21: Cash Vouchers | O21: Jobsheets | P21: Cash Vouchers | Q21: Jobsheets | R21: Cash Vouchers | S21: Jobsheets | T21: Cash Vouchers | U21: Jobsheets | V21: Cash Vouchers | W21: Jobsheets | X21: Cash Vouchers
A22: 2017.05 | B22: 496.9 | C22: 1907.36 | D22: 2243.4 | E22: 150 | F22: 553.8 | G22: 1807.67 | I22: 4574.9 | K22: 2820 | L22: 57.5 | M22: 2700 | N22: 47.5 | O22: 2640 | P22: 50 | Q22: 1860 | R22: 4500 | S22: 60 | U22: 2560 | V22: 42.5 | W22: 2640 | X22: 60
A23: 368.1 | B23: 1687.98 | C23: 459.65 | D23: 388.1 | F23: 1937.36 | G23: 500.58 | I23: 1253.72 | K23: 1975 | L23: 240 | M23: 1765 | N23: 700 | O23: 2205 | Q23: 1540 | R23: 30 | S23: 150 | U23: 1905 | V23: 60 | W23: 1865 | X23: 50
B24: 914.65 | F24: 671.2 | I24: 510.42 | K24: 180 | L24: 26 | M24: 835 | O24: 675 | Q24: 450 | R24: 17 | S24: 150 | U24: 785 | W24: 60 | X24: 150
I25: 4797.26 | K25: 515 | M25: 300 | O25: 144 | Q25: 228 | S25: 84 | U25: 300 | W25: 1335 | X25: 372
I26: 4425 | K26: 222 | M26: 72 | Q26: 72 | W26: 326
I27: 700
I28: =SUM(I21:I27) -> 21127.33 | W28: 90 | Y28: =SUM(Y21:Y26) -> 0
A36: =SUM(A21:A35) -> 3512.05 | B36: =SUM(B21:B35) -> 3847.98 | C36: =SUM(C21:C35) -> 3707.36 | D36: =SUM(D21:D35) -> 3648.4 | E36: =SUM(E21:E35) -> 335 | F36: =SUM(F21:F35) -> 4052.36 | G36: =SUM(G21:G35) -> 3562.05 | H36: =SUM(A36:G36)+I28 -> 43792.53 | I36: OASys Value | K36: =SUM(K22:K35) -> 5712 | L36: =SUM(L22:L35) -> 323.5 | M36: =SUM(M22:M35) -> 5672 | N36: =SUM(N22:N35) -> 747.5 | O36: =SUM(O22:O35) -> 5664 | P36: =SUM(P22:P35) -> 50 | Q36: =SUM(Q22:Q35) -> 4150 | R36: =SUM(R22:R35) -> 4547 | ... X36: =SUM(X22:X35) -> 632 | Y36: =K37+M37+O37+Q37+S37+U37+W37 -> 33508
A37: 3512.05 | B37: 3847.98 | C37: 3707.36 | D37: 3648.4 | E37: 335 | F37: 4052.36 | G37: 3562.05 | H37: =SUM(A37:G37)+I28 -> 43792.53 | I37: Payroll Value | K37: 5712 | L37: 323.5 | M37: 5672 | N37: 747.5 | O37: 5664 | P37: 50 | Q37: 4150 | R37: 4547 | S37: 444 | T37: 0 | U37: 5550 | V37: 102.5 | W37: 6316 | X37: 632 | Y37: =L37+N37+P37+R37+T37+V37+X37 -> 6402.5
A38: =A36-A37 -> 0 | B38: =B36-B37 -> 0 | C38: =C36-C37 -> 0 | D38: =D36-D37 -> 0 | E38: =E36-E37 -> 0 | F38: =F36-F37 -> 0 | G38: =G36-G37 -> 0 | H38: =H36-H37 -> 0 | K38: =K36-K37 -> 0 | L38: =L36-L37 -> 0 | M38: =M36-M37 -> 0 | N38: =N36-N37 -> 0 | O38: =O36-O37 -> 0 | P38: =P36-P37 -> 0 | Q38: =Q36-Q37 -> 0 | R38: =R36-R37 -> 0 | ... X38: =X36-X37 -> 0
A40: 45063 | B40: 45064 | C40: 45065 | D40: 45066 | E40: 45067 | F40: 45068 | G40: 45069 | I40: Registers | K40: 45063 | M40: 45064 | O40: 45065 | Q40: 45066 | S40: 45067 | U40: 45068 | W40: 45069
A41: 1628.8 | B41: 1583.8 | C41: 1293.9 | D41: 1005.35 | E41: 185 | F41: 1300.35 | G41: 515 | I41: 4570 | K41: Jobsheets | L41: Cash Vouchers | M41: Jobsheets | N41: Cash Vouchers | O41: Jobsheets | P41: Cash Vouchers | Q41: Jobsheets | R41: Cash Vouchers | S41: Jobsheets | T41: Cash Vouchers | U41: Jobsheets | V41: Cash Vouchers | W41: Jobsheets | X41: Cash Vouchers
A42: 1787.05 | B42: 2059.86 | C42: 1647.05 | D42: 2468.28 | E42: 185 | F42: 2212.98 | G42: 525.35 | I42: 5904.32 | K42: 2460 | L42: 86 | M42: 2370 | N42: 50 | O42: 2740 | P42: 10 | Q42: 1900 | R42: 22.5 | S42: 60 | U42: 2710 | V42: 50 | W42: 2650 | X42: 222.5
A43: 606.2 | B43: 536.2 | C43: 961.1 | D43: 349.65 | F43: 649.65 | G43: 2079.6 | I43: 4990.8 | K43: 2155 | L43: 42.5 | M43: 2165 | N43: 60 | O43: 2645 | P43: 7.5 | Q43: 1420 | S43: 60 | U43: 1915 | V43: 100 | W43: 1590 | X43: 60
G44: 302.45 | I44: 6418.42 | K44: 885 | L44: 20 | M44: 1355 | O44: 635 | Q44: 640 | S44: 210 | U44: 290 | W44: 540 | X44: 60
G45: 269.65 | K45: 222 | M45: 324 | O45: 144 | Q45: 254 | S45: 72 | U45: 195 | W45: 1190
M46: 72 | Q46: 90 | U46: 324 | W46: 300
W47: 72
I48: =SUM(I41:I47) -> 21883.54 | Y48: =SUM(Y41:Y46) -> 0
A56: =SUM(A41:A55) -> 4022.05 | B56: =SUM(B41:B55) -> 4179.86 | C56: =SUM(C41:C55) -> 3902.05 | D56: =SUM(D41:D55) -> 3823.28 | E56: =SUM(E41:E55) -> 370 | F56: =SUM(F41:F55) -> 4162.98 | G56: =SUM(G41:G55) -> 3692.05 | H56: =SUM(A56:G56)+I48 -> 46035.81 | I56: OASys Value | K56: =SUM(K42:K55) -> 5722 | L56: =SUM(L42:L55) -> 148.5 | M56: =SUM(M42:M55) -> 6286 | N56: =SUM(N42:N55) -> 110 | O56: =SUM(O42:O55) -> 6164 | P56: =SUM(P42:P55) -> 17.5 | Q56: =SUM(Q42:Q55) -> 4304 | R56: =SUM(R42:R55) -> 22.5 | ... X56: =SUM(X42:X55) -> 342.5 | Y56: =K57+M57+O57+Q57+S57+U57+W57 -> 34654
A57: 4022.05 | B57: 4179.86 | C57: 3902.05 | D57: 3823.28 | E57: 370 | F57: 4162.98 | G57: 3692.05 | H57: =SUM(A57:G57)+I48 -> 46035.81 | I57: Payroll Value | K57: 5722 | L57: 148.5 | M57: 6286 | N57: 110 | O57: 6164 | P57: 17.5 | Q57: 4304 | R57: 22.5 | S57: 402 | T57: 0 | U57: 5434 | V57: 150 | W57: 6342 | X57: 342 | Y57: =L57+N57+P57+R57+T57+V57+X57 -> 790.5
A58: =A56-A57 -> 0 | B58: =B56-B57 -> 0 | C58: =C56-C57 -> 0 | D58: =D56-D57 -> 0 | E58: =E56-E57 -> 0 | F58: =F56-F57 -> 0 | G58: =G56-G57 -> 0 | K58: =K56-K57 -> 0 | L58: =L56-L57 -> 0 | M58: =M56-M57 -> 0 | N58: =N56-N57 -> 0 | O58: =O56-O57 -> 0 | P58: =P56-P57 -> 0 | Q58: =Q56-Q57 -> 0 | R58: =R56-R57 -> 0 | ... X58: =X56-X57 -> 0.5
A60: 45070 | B60: 45071 | C60: 45072 | D60: 45073 | E60: 45074 | F60: 45075 | G60: 45076 | I60: Registers | K60: 45070 | M60: 45071 | O60: 45072 | Q60: 45073 | S60: 45074 | U60: 45075 | W60: 45076
A61: 3235.52 | B61: 1080.35 | C61: 1768.8 | D61: 976.9 | E61: 185 | F61: 1288.8 | G61: 2456.6 | I61: 5535.3 | K61: Jobsheets | L61: Cash Vouchers | M61: Jobsheets | N61: Cash Vouchers | O61: Jobsheets | P61: Cash Vouchers | Q61: Jobsheets | R61: Cash Vouchers | S61: Jobsheets | T61: Cash Vouchers | U61: Jobsheets | V61: Cash Vouchers | W61: Jobsheets | X61: Cash Vouchers
B62: 1314.96 | C62: 1862.1 | D62: 138.45 | F62: 2068.5 | G62: 782.45 | I62: 5238.82 | K62: 2520 | L62: 1600 | M62: 310 | N62: 27.5 | O62: 3390 | P62: 1620 | Q62: 2050 | R62: 720 | S62: 120 | U62: 2700 | V62: 600 | W62: 4250 | X62: 1620
A63: 609.65 | B63: 274.65 | C63: 311.2 | D63: 2304.54 | F63: 666.2 | G63: 253.1 | I63: 4755 | K63: 1985 | L63: 42.5 | M63: 1010 | O63: 2805 | P63: 89 | Q63: 1240 | R63: 60 | S63: 210 | U63: 2030 | V63: 372 | W63: 60 | X63: 47.5
...

Sheet June 2023
A1: 45077 | B1: 45078 | C1: 45079 | D1: 45080 | E1: 45081 | F1: 45082 | G1: 45083 | I1: Registers | K1: 45077 | M1: 45078 | O1: 45079 | Q1: 45080 | S1: 45081 | U1: 45082 | W1: 45083
A2: 3375.52 | B2: 1485.35 | C2: 1375.35 | D2: 901.9 | E2: 185 | F2: 693.45 | G2: 1375.35 | I2: 5535.3 | K2: Jobsheets | L2: Cash Vouchers | M2: Jobsheets | N2: Cash Vouchers | O2: Jobsheets | P2: Cash Vouchers | Q2: Jobsheets | R2: Cash Vouchers | S2: Jobsheets | T2: Cash Vouchers | U2: Jobsheets | V2: Cash Vouchers | W2: Jobsheets | X2: Cash Vouchers
A3: 624.65 | B3: 1957.67 | C3: 1817.98 | D3: 2463.9 | E3: 185 | F3: 635.35 | G3: 1837.67 | I3: 4741.26 | K3: 4515 | L3: 152.5 | M3: 2460 | N3: 50 | O3: 2730 | P3: 65 | Q3: 2170 | R3: 3660 | S3: 60 | T3: 0 | U3: 2810 | V3: 863.7 | W3: 2320 | X3: 57.5
B4: 624.65 | C4: 389.65 | D4: 458.1 | E4: 110 | F4: 1692.15 | G4: 674.65 | I4: 350 | K4: 385 | L4: 50 | M4: 1555 | O4: 1960 | Q4: 1120 | R4: 57.5 | S4: 60 | U4: 2235 | W4: 3630 | X4: 10
F5: 751.2 | I5: 5533.72 | K5: 248 | M5: 875 | O5: 520 | Q5: 320 | S5: 120 | U5: 180 | W5: 810
I6: 1179.6 | M6: 300 | O6: 144 | Q6: 228 | S6: 72 | U6: 160 | W6: 288
I7: 4115 | M7: 72 | Q7: 96 | U7: 195 | W7: 96
I8: =SUM(I2:I7) -> 21454.88 | U8: 300
Y9: =SUM(Y2:Y7) -> 0
A16: =SUM(A2:A15) -> 4000.17 | B16: =SUM(B2:B15) -> 4067.67 | C16: =SUM(C2:C15) -> 3582.98 | D16: =SUM(D2:D15) -> 3823.9 | E16: =SUM(E2:E15) -> 480 | F16: =SUM(F2:F15) -> 3772.15 | G16: =SUM(G2:G15) -> 3887.67 | H16: =SUM(A16:G16)+I8 -> 45069.42 | I16: OASys Value | K16: =SUM(K3:K15) -> 5148 | L16: =SUM(L3:L15) -> 202.5 | M16: =SUM(M3:M15) -> 5262 | N16: =SUM(N3:N15) -> 50 | O16: =SUM(O3:O15) -> 5354 | P16: =SUM(P3:P15) -> 65 | Q16: =SUM(Q3:Q15) -> 3934 | R16: =SUM(R3:R15) -> 3717.5 | ... X16: =SUM(X3:X15) -> 67.5 | Y16: =K17+M17+O17+Q17+S17+U17+W17 -> 33034
A17: 4000.17 | B17: 4067.67 | C17: 3582.98 | D17: 3823.9 | E17: 480 | F17: 3772.15 | G17: 3887.67 | H17: =SUM(A17:G17)+I8 -> 45069.42 | I17: Payroll Value | K17: 5148 | L17: 202.5 | M17: 5262 | N17: 50 | O17: 5354 | P17: 65 | Q17: 3934 | R17: 3717.5 | S17: 312 | T17: 0 | U17: 5880 | V17: 863.7 | W17: 7144 | X17: 67.5 | Y17: =L17+N17+P17+R17+T17+V17+X17 -> 4966.2
A18: =A16-A17 -> 0 | B18: =B16-B17 -> 0 | C18: =C16-C17 -> 0 | D18: =D16-D17 -> 0 | E18: =E16-E17 -> 0 | F18: =F16-F17 -> 0 | G18: =G16-G17 -> 0 | K18: =K16-K17 -> 0 | L18: =L16-L17 -> 0 | M18: =M16-M17 -> 0 | N18: =N16-N17 -> 0 | O18: =O16-O17 -> 0 | P18: =P16-P17 -> 0 | Q18: =Q16-Q17 -> 0 | R18: =R16-R17 -> 0 | ... X18: =X16-X17 -> 0
A20: 45084 | B20: 45085 | C20: 45086 | D20: 45087 | E20: 45088 | F20: 45089 | G20: 45090 | I20: Registers | K20: 45084 | M20: 45085 | O20: 45086 | Q20: 45087 | S20: 45088 | U20: 45089 | W20: 45090
A21: 1595.35 | B21: 1190.35 | C21: 1375.35 | D21: 1005.35 | E21: 370 | F21: 913.45 | G21: 1443.8 | I21: 4795 | K21: Jobsheets | L21: Cash Vouchers | M21: Jobsheets | N21: Cash Vouchers | O21: Jobsheets | P21: Cash Vouchers | Q21: Jobsheets | R21: Cash Vouchers | S21: Jobsheets | T21: Cash Vouchers | U21: Jobsheets | V21: Cash Vouchers | W21: Jobsheets | X21: Cash Vouchers
A22: 1757.36 | B22: 110 | C22: 138.45 | D22: 2524.54 | F22: 525.35 | G22: 2027.05 | I22: 5535.3 | K22: 4010 | L22: 65 | M22: 3340 | N22: 65 | O22: 3640 | P22: 60 | Q22: 2220 | R22: 780 | S22: 120 | U22: 4190 | V22: 117.5 | W22: 3990 | X22: 50
A23: 594.65 | B23: 2203.19 | C23: 1850.43 | D23: 429.65 | F23: 110 | G23: 406.2 | I23: 5165.1 | K23: 2145 | M23: 1425 | N23: 372 | O23: 2155 | P23: 77.5 | Q23: 1440 | R23: 50 | S23: 420 | U23: 2525 | W23: 1820 | X23: 24
B24: 374.65 | C24: 571.2 | F24: 1857.05 | I24: 4866.03 | K24: 615 | M24: 1085 | O24: 1075 | P24: 185 | Q24: 590 | S24: 72 | U24: 65 | W24: 700
F25: 646.2 | I25: 431.04 | K25: 222 | M25: 300 | O25: 144 | Q25: 348 | U25: 396 | W25: 300
I26: 350 | K26: 74 | M26: 72 | Q26: 72 | U26: 13 | W26: 72
I27: =SUM(I21:I26) -> 21142.47
Y28: =SUM(Y21:Y26) -> 0
A35: =SUM(A21:A34) -> 3947.36 | B35: =SUM(B21:B34) -> 3878.19 | C35: =SUM(C21:C34) -> 3935.43 | D35: =SUM(D21:D34) -> 3959.54 | E35: =SUM(E21:E34) -> 370 | F35: =SUM(F21:F34) -> 4052.05 | G35: =SUM(G21:G34) -> 3877.05 | H35: =SUM(A35:G35)+I27 -> 45162.09 | I35: OASys Value | K35: =SUM(K22:K34) -> 7066 | L35: =SUM(L22:L34) -> 65 | M35: =SUM(M22:M34) -> 6222 | N35: =SUM(N22:N34) -> 437 | O35: =SUM(O22:O34) -> 7014 | P35: =SUM(P22:P34) -> 322.5 | Q35: =SUM(Q22:Q34) -> 4670 | R35: =SUM(R22:R34) -> 830 | ... X35: =SUM(X22:X34) -> 74 | Y35: =K36+M36+O36+Q36+S36+U36+W36 -> 39655
A36: 3947.36 | B36: 3878.19 | C36: 3935.43 | D36: 3959.54 | E36: 370 | F36: 4052.05 | G36: 3877.05 | H36: =SUM(A36:G36)+I27 -> 45162.09 | I36: Payroll Value | K36: 7066 | L36: 65 | M36: 6222 | N36: 437 | O36: 7014 | P36: 322.5 | Q36: 4670 | R36: 830 | S36: 612 | T36: 0 | U36: 7189 | V36: 117.5 | W36: 6882 | X36: 74 | Y36: =L36+N36+P36+R36+T36+V36+X36 -> 1846
A37: =A35-A36 -> 0 | B37: =B35-B36 -> 0 | C37: =C35-C36 -> 0 | D37: =D35-D36 -> 0 | E37: =E35-E36 -> 0 | F37: =F35-F36 -> 0 | G37: =G35-G36 -> 0 | K37: =K35-K36 -> 0 | L37: =L35-L36 -> 0 | M37: =M35-M36 -> 0 | N37: =N35-N36 -> 0 | O37: =O35-O36 -> 0 | P37: =P35-P36 -> 0 | Q37: =Q35-Q36 -> 0 | R37: =R35-R36 -> 0 | ... X37: =X35-X36 -> 0
A39: 45091 | B39: 45092 | C39: 45093 | D39: 45094 | E39: 45095 | F39: 45096 | G39: 45097 | I39: Registers | K39: 45091 | M39: 45092 | O39: 45093 | Q39: 45094 | S39: 45095 | U39: 45096 | W39: 45097
A40: 1438.8 | B40: 775 | C40: 578.45 | D40: 1126.9 | E40: 370 | F40: 700 | G40: 1306.9 | I40: 5828.62 | K40: Jobsheets | L40: Cash Vouchers | M40: Jobsheets | N40: Cash Vouchers | O40: Jobsheets | P40: Cash Vouchers | Q40: Jobsheets | R40: Cash Vouchers | S40: Jobsheets | T40: Cash Vouchers | U40: Jobsheets | V40: Cash Vouchers | W40: Jobsheets | X40: Cash Vouchers
A41: 1919.55 | B41: 1559.67 | C41: 1016.9 | D41: 110 | E41: 220 | F41: 606.9 | G41: 2042.98 | I41: 5904.32 | K41: 4790 | L41: 3397 | M41: 5130 | N41: 5130 | O41: 4890 | P41: 65 | Q41: 1800 | R41: 57.5 | S41: 120 | U41: 5040 | V41: 197 | W41: 4640 | X41: 60
A42: 436.2 | B42: 1297.4 | C42: 407.5 | D42: 2548.28 | F42: 1707.67 | G42: 278.1 | I42: 4630 | K42: 1625 | L42: 26 | M42: 1690 | N42: 1690 | O42: 1610 | P42: 240 | Q42: 970 | R42: 60 | S42: 240 | U42: 2380 | V42: 180 | W42: 2045 | X42: 372
B43: 488.1 | C43: 324.65 | D43: 383.1 | F43: 393.1 | I43: 4505.6 | K43: 195 | L43: 42.5 | M43: 970 | N43: 970 | O43: 340 | Q43: 300 | S43: 72 | U43: 620 | W43: 775 | X43: 52.5
I44: 1451.88 | K44: 222 | L44: 20 | M44: 300 | N44: 300 | O44: 144 | Q44: 228 | U44: 300 | W44: 300 | X44: 500
I45: 1010 | M45: 98 | N45: 98 | Q45: 96 | W45: 72
I46: =SUM(I40:I45) -> 23330.42
Y47: =SUM(Y40:Y45) -> 0
A54: =SUM(A40:A53) -> 3794.55 | B54: =SUM(B40:B53) -> 4120.17 | C54: =SUM(C40:C53) -> 2327.5 | D54: =SUM(D40:D53) -> 4168.28 | E54: =SUM(E40:E53) -> 590 | F54: =SUM(F40:F53) -> 3407.67 | G54: =SUM(G40:G53) -> 3627.98 | H54: =SUM(A54:G54)+I46 -> 45366.57 | I54: OASys Value | K54: =SUM(K41:K53) -> 6832 | L54: =SUM(L41:L53) -> 3485.5 | M54: =SUM(M41:M53) -> 8188 | N54: =SUM(N41:N53) -> 8188 | O54: =SUM(O41:O53) -> 6984 | P54: =SUM(P41:P53) -> 305 | Q54: =SUM(Q41:Q53) -> 3394 | R54: =SUM(R41:R53) -> 117.5 | ... X54: =SUM(X41:X53) -> 984.5 | Y54: =K55+M55+O55+Q55+S55+U55+W55 -> 42002
A55: 3794.55 | B55: 4120.17 | C55: 2327.5 | D55: 4168.28 | E55: 590 | F55: 3407.67 | G55: 3627.98 | H55: =SUM(A55:G55)+I46 -> 45366.57 | I55: Payroll Value | K55: 6832 | L55: 3485.5 | M55: 8188 | N55: 8188 | O55: 6984 | P55: 305 | Q55: 3394 | R55: 117.5 | S55: 432 | T55: 0 | U55: 8340 | V55: 377 | W55: 7832 | X55: 984.5 | Y55: =L55+N55+P55+R55+T55+V55+X55 -> 13457.5
A56: =A54-A55 -> 0 | B56: =B54-B55 -> 0 | C56: =C54-C55 -> 0 | D56: =D54-D55 -> 0 | E56: =E54-E55 -> 0 | F56: =F54-F55 -> 0 | G56: =G54-G55 -> 0 | K56: =K54-K55 -> 0 | L56: =L54-L55 -> 0 | M56: =M54-M55 -> 0 | N56: =N54-N55 -> 0 | O56: =O54-O55 -> 0 | P56: =P54-P55 -> 0 | Q56: =Q54-Q55 -> 0 | R56: =R54-R55 -> 0 | ... V56: =V54-V55 -> 0 | W56: =X511 -> 0 | X56: =X54-X55 -> 0
A58: 45098 | B58: 45099 | C58: 45100 | D58: 45101 | E58: 45102 | F58: 45103 | G58: 45104 | I58: Registers | K58: 45098 | M58: 45099 | O58: 45100 | Q58: 45101 | S58: 45102 | U58: 45103 | W58: 45104
A59: 1463.45 | B59: 653.45 | C59: 1711.9 | D59: 920 | E59: 480 | F59: 440 | G59: 948.45 | I59: 5125 | K59: Jobsheets | L59: Cash Vouchers | M59: Jobsheets | N59: Cash Vouchers | O59: Jobsheets | P59: Cash Vouchers | Q59: Jobsheets | R59: Cash Vouchers | S59: Jobsheets | T59: Cash Vouchers | U59: Jobsheets | V59: Cash Vouchers | W59: Jobsheets | X59: Cash Vouchers
A60: 1992.67 | B60: 693.45 | C60: 1919.55 | D60: 2444.54 | F60: 976.9 | G60: 358.45 | I60: 5535.3 | K60: 1925
A61: 541.55 | B61: 1849.86 | C61: 243.1 | D61: 330 | F61: 2017.67 | G61: 1802.46 | I61: 5828.62 | K61: 1715
...

Sheet July 2023
A1: 45105 | B1: 45106 | C1: 45107 | D1: 45108 | E1: 45109 | F1: 45110 | G1: 45111 | I1: Registers | K1: 45105 | M1: 45106 | O1: 45107 | Q1: 45108 | S1: 45109 | U1: 45110 | W1: 45111
A2: 1526.9 | B2: 653.45 | C2: 1341.9 | D2: 735 | E2: 580 | F2: 820 | G2: 1150 | I2: 6797.4 | K2: Jobsheets | L2: Cash Vouchers | M2: Jobsheets | N2: Cash Vouchers | O2: Jobsheets | P2: Cash Vouchers | Q2: Jobsheets | R2: Cash Vouchers | S2: Jobsheets | T2: Cash Vouchers | U2: Jobsheets | V2: Cash Vouchers | W2: Jobsheets | X2: Cash Vouchers
A3: 1884.65 | B3: 895.35 | C3: 1720.17 | D3: 1517.86 | E3: 120 | F3: 2760.47 | G3: 2850.47 | I3: 6085 | K3: 5400 | L3: 57.5 | M3: 5490 | N3: 57.5 | O3: 5480 | P3: 240 | Q3: 710 | R3: 42.5 | S3: 240 | U3: 1950 | V3: 460 | W3: 1760 | X3: 102.5
A4: 593.1 | B4: 1880.48 | C4: 488.1 | D4: 480 | G4: 475 | I4: 3793.52 | K4: 1800 | L4: 27.9 | M4: 1600 | O4: 2500 | P4: 65 | Q4: 1290 | S4: 140 | U4: 2710 | V4: 52.9 | W4: 2170
B5: 346.2 | F5: 920 | I5: 1410.51 | K5: 130 | L5: 120 | M5: 770 | O5: 470 | P5: 320 | Q5: 520 | S5: 72 | U5: 350 | W5: 880
I6: 862.08 | K6: 222 | M6: 300 | O6: 516 | Q6: 228 | U6: 300 | W6: 372
I7: 3598.38 | K7: 30 | M7: 72 | Q7: 102 | U7: 26 | W7: 72
I8: =SUM(I2:I7) -> 22546.89
Y9: =SUM(Y2:Y7) -> 0
A16: =SUM(A2:A15) -> 4004.65 | B16: =SUM(B2:B15) -> 3775.48 | C16: =SUM(C2:C15) -> 3550.17 | D16: =SUM(D2:D15) -> 2732.86 | E16: =SUM(E2:E15) -> 700 | F16: =SUM(F2:F15) -> 4500.47 | G16: =SUM(G2:G15) -> 4475.47 | H16: =SUM(A16:G16)+I8 -> 46285.99 | I16: OASys Value | K16: =SUM(K3:K15) -> 7582 | L16: =SUM(L3:L15) -> 205.4 | M16: =SUM(M3:M15) -> 8232 | N16: =SUM(N3:N15) -> 57.5 | O16: =SUM(O3:O15) -> 8966 | P16: =SUM(P3:P15) -> 625 | Q16: =SUM(Q3:Q15) -> 2850 | R16: =SUM(R3:R15) -> 42.5 | ... X16: =SUM(X3:X15) -> 102.5 | Y16: =K17+M17+O17+Q17+S17+U17+W17 -> 38672
A17: 4004.65 | B17: 3775.48 | C17: 3550.17 | D17: 2732.86 | E17: 700 | F17: 4500.47 | G17: 4475.47 | H17: =SUM(A17:G17)+I8 -> 46285.99 | I17: Payroll Value | K17: 7582 | L17: 205.4 | M17: 8232 | N17: 57.5 | O17: 8966 | P17: 625 | Q17: 2850 | R17: 42.5 | S17: 452 | T17: 0 | U17: 5336 | V17: 512 | W17: 5254 | X17: 102.5 | Y17: =L17+N17+P17+R17+T17+V17+X17 -> 1544.9
A18: =A16-A17 -> 0 | B18: =B16-B17 -> 0 | C18: =C16-C17 -> 0 | D18: =D16-D17 -> 0 | E18: =E16-E17 -> 0 | F18: =F16-F17 -> 0 | G18: =G16-G17 -> 0 | K18: =K16-K17 -> 0 | L18: =L16-L17 -> 0 | M18: =M16-M17 -> 0 | N18: =N16-N17 -> 0 | O18: =O16-O17 -> 0 | P18: =P16-P17 -> 0 | Q18: =Q16-Q17 -> 0 | R18: =R16-R17 -> 0 | ... X18: =X16-X17 -> 0
A20: 45112 | B20: 45113 | C20: 45114 | D20: 45115 | E20: 45116 | F20: 45117 | G20: 45118 | I20: Registers | K20: 45112 | M20: 45113 | O20: 45114 | Q20: 45115 | S20: 45116 | U20: 45117 | W20: 45118
A21: 1150 | B21: 1020 | C21: 1375 | D21: 685 | E21: 240 | F21: 1045 | G21: 750 | I21: 5922.75 | K21: Jobsheets | L21: Cash Vouchers | M21: Jobsheets | N21: Cash Vouchers | O21: Jobsheets | P21: Cash Vouchers | Q21: Jobsheets | R21: Cash Vouchers | S21: Jobsheets | T21: Cash Vouchers | U21: Jobsheets | V21: Cash Vouchers | W21: Jobsheets | X21: Cash Vouchers
A22: 2827.97 | B22: 2463.06 | C22: 2480.56 | D22: 870 | F22: 2623 | G22: 2463 | I22: 5289.97 | K22: 1730 | L22: 156.5 | M22: 1850 | N22: 42.5 | O22: 1550 | P22: 1500 | Q22: 770 | R22: 2040 | S22: 480 | U22: 1840 | V22: 80 | W22: 2080 | X22: 42.5
A23: 565 | B23: 585 | C23: 405 | D23: 610 | F23: 185 | G23: 710 | I23: 4755 | K23: 3525 | M23: 2055 | N23: 26.1 | O23: 2445 | P23: 50 | Q23: 1450 | R23: 60 | S23: 140 | U23: 2720 | W23: 2115 | X23: 65
F24: 1095 | I24: 780 | K24: 575 | M24: 1075 | O24: 605 | P24: 2000 | Q24: 440 | S24: 140 | U24: 920 | W24: 1465
I25: 4005.15 | K25: 222 | M25: 300 | O25: 144 | Q25: 348 | S25: 72 | U25: 300 | W25: 300
M26: 72 | Q26: 96 | W26: 72
I27: =SUM(I21:I26) -> 20752.87
Y28: =SUM(Y21:Y26) -> 0
AA33: 13892
AA34: 657
A35: =SUM(A21:A34) -> 4542.97 | B35: =SUM(B21:B34) -> 4068.06 | C35: =SUM(C21:C34) -> 4260.56 | D35: =SUM(D21:D34) -> 2165 | E35: =SUM(E21:E34) -> 240 | F35: =SUM(F21:F34) -> 4948 | G35: =SUM(G21:G34) -> 3923 | H35: =SUM(A35:G35)+I27 -> 44900.46 | I35: OASys Value | K35: =SUM(K22:K34) -> 6052 | L35: =SUM(L22:L34) -> 156.5 | M35: =SUM(M22:M34) -> 5352 | N35: =SUM(N22:N34) -> 68.6 | O35: =SUM(O22:O34) -> 4744 | P35: =SUM(P22:P34) -> 3550 | Q35: =SUM(Q22:Q34) -> 3104 | R35: =SUM(R22:R34) -> 2100 | ... X35: =SUM(X22:X34) -> 107.5 | Y35: =K36+M36+O36+Q36+S36+U36+W36 -> 31896 | AA35: =Y35 -> 31896
A36: 4542.97 | B36: 4068.06 | C36: 4260.56 | D36: 2165 | E36: 240 | F36: 4948 | G36: 3923 | H36: =SUM(A36:G36)+I27 -> 44900.46 | I36: Payroll Value | K36: 6052 | L36: 156.5 | M36: 5352 | N36: 68.6 | O36: 4744 | P36: 3550 | Q36: 3104 | R36: 2100 | S36: 832 | T36: 0 | U36: 5780 | V36: 80 | W36: 6032 | X36: 107.5 | Y36: =L36+N36+P36+R36+T36+V36+X36 -> 6062.6 | AA36: =Y36 -> 6062.6
A37: =A35-A36 -> 0 | B37: =B35-B36 -> 0 | C37: =C35-C36 -> 0 | D37: =D35-D36 -> 0 | E37: =E35-E36 -> 0 | F37: =F35-F36 -> 0 | G37: =G35-G36 -> 0 | K37: =K35-K36 -> 0 | L37: =L35-L36 -> 0 | M37: =M35-M36 -> 0 | N37: =N35-N36 -> 0 | O37: =O35-O36 -> 0 | P37: =P35-P36 -> 0 | Q37: =Q35-Q36 -> 0 | R37: =R35-R36 -> 0 | ... X37: =X35-X36 -> 0 | AA37: =Y54 -> 28690
AA38: =Y55 -> 3203.5
A39: 45119 | B39: 45120 | C39: 45121 | D39: 45122 | E39: 45123 | F39: 45124 | G39: 45125 | I39: Registers | K39: 45119 | M39: 45120 | O39: 45121 | Q39: 45122 | R39: 45123 | S39: 45123 | U39: 45124 | W39: 45125 | AA39: =Y73 -> 27112
A40: 1325 | B40: 1320 | C40: 1120 | D40: 210 | E40: 325 | F40: 910 | G40: 1200 | I40: 5922.75 | K40: Jobsheets | L40: Cash Vouchers | M40: Jobsheets | N40: Cash Vouchers | O40: Jobsheets | P40: Cash Vouchers | Q40: Jobsheets | R40: Cash Vouchers | S40: Jobsheets | T40: Cash Vouchers | U40: Jobsheets | V40: Cash Vouchers | W40: Jobsheets | X40: Cash Vouchers | AA40: =Y74 -> 3932.5
A41: 2747.97 | B41: 2423.09 | C41: 2593.06 | D41: 410 | F41: 2319.99 | G41: 2412.82 | I41: 2620 | K41: 1670 | L41: 1500 | M41: 1580 | N41: 60 | O41: 1820 | P41: 50 | Q41: 870 | R41: 50 | S41: 480 | U41: 1950 | V41: 50 | W41: 1790 | X41: 77.9 | AA41: =Y92 -> 27948
A42: 690 | B42: 820 | C42: 605 | D42: 1266.14 | F42: 940 | G42: 640 | I42: 2690 | K42: 1965 | L42: 42.5 | M42: 1765 | N42: 372 | O42: 2065 | P42: 30 | Q42: 140 | S42: 70 | U42: 1930 | V42: 731.1 | W42: 1515 | AA42: =Y93 -> 5048.4
D43: 560 | I43: 4005.15 | K43: 1155 | M43: 1635 | N43: 90 | O43: 695 | Q43: 590 | S43: 140 | U43: 510 | W43: 905 | AA43: =SUM(AA33:AA42) -> 148442
I44: 5389.97 | K44: 222 | M44: 300 | N44: 150 | O44: 144 | Q44: 510 | S44: 72 | U44: 1110 | W44: 300
I45: 461.2 | M45: 72 | Q45: 276 | U45: 300 | W45: 72
I46: =SUM(I40:I45) -> 21089.07 | Q46: 72
Y47: =SUM(Y40:Y45) -> 0
B52: 555
A54: =SUM(A40:A53) -> 4762.97 | B54: =SUM(B40:B53) -> 5118.09 | C54: =SUM(C40:C53) -> 4318.06 | D54: =SUM(D40:D53) -> 2446.14 | E54: =SUM(E40:E53) -> 325 | F54: =SUM(F40:F53) -> 4169.99 | G54: =SUM(G40:G53) -> 4252.82 | H54: =SUM(A54:G54)+I46 -> 46482.14 | I54: OASys Value | K54: =SUM(K41:K53) -> 5012 | L54: =SUM(L41:L53) -> 1542.5 | M54: =SUM(M41:M53) -> 5352 | N54: =SUM(N41:N53) -> 672 | O54: =SUM(O41:O53) -> 4724 | P54: =SUM(P41:P53) -> 80 | Q54: =SUM(Q41:Q53) -> 2458 | R54: =SUM(R41:R53) -> 50 | ... X54: =SUM(X41:X53) -> 77.9 | Y54: =K55+M55+O55+Q55+S55+U55+W55 -> 28690
A55: 4762.97 | B55: 4563.09 | C55: 4318.06 | D55: 2446.14 | E55: 325 | F55: 4169.99 | G55: 4252.82 | H55: =SUM(A55:G55)+I46 -> 45927.14 | I55: Payroll Value | K55: 5012 | L55: 1542.5 | M55: 5352 | N55: 672 | O55: 4724 | P55: 80 | Q55: 2458 | R55: 50 | S55: 762 | U55: 5800 | V55: 781.1 | W55: 4582 | X55: 77.9 | Y55: =L55+N55+P55+R54+T55+V55+X55 -> 3203.5
A56: =A54-A55 -> 0 | B56: =B54-B55 -> 555 | C56: =C54-C55 -> 0 | D56: =D54-D55 -> 0 | E56: =E54-E55 -> 0 | F56: =F54-F55 -> 0 | G56: =G54-G55 -> 0 | K56: =K54-K55 -> 0 | L56: =L54-L55 -> 0 | M56: =M54-M55 -> 0 | N56: =N54-N55 -> 0 | O56: =O54-O55 -> 0 | P56: =P54-P55 -> 0 | Q56: =Q54-Q55 -> 0 | R56: =R54-R55 -> 0 | ... X56: =X54-X55 -> 0
...

Sheet August 2023
A1: 45140 | B1: 45141 | C1: 45142 | D1: 45143 | E1: 45144 | F1: 45145 | G1: 45146 | I1: Registers | K1: 45140 | M1: 45141 | O1: 45142 | Q1: 45143 | S1: 45144 | U1: 45145 | W1: 45146
A2: 890 | B2: 860 | C2: 995 | D2: 710 | E2: 120 | F2: 855 | G2: 950 | I2: 5922.75 | K2: Jobsheets | L2: Cash Vouchers | M2: Jobsheets | N2: Cash Vouchers | O2: Jobsheets | P2: Cash Vouchers | Q2: Jobsheets | R2: Cash Vouchers | S2: Jobsheets | T2: Cash Vouchers | U2: Jobsheets | V2: Cash Vouchers | W2: Jobsheets | X2: Cash Vouchers
A3: 2327.46 | B3: 3053.06 | C3: 2087.46 | D3: 1747.88 | E3: 85 | F3: 2242.16 | G3: 1937.16 | I3: 3430 | K3: 1370 | L3: 60 | M3: 1380 | N3: 24 | O3: 1300 | P3: 130 | Q3: 780 | R3: 42.5 | S3: 480 | T3: 0 | U3: 2220 | V3: 372 | W3: 2630
A4: 450 | B4: 655 | C4: 305 | D4: 505 | F4: 575 | G4: 265 | I4: 4005 | K4: 1870 | L4: 237.5 | M4: 1480 | N4: 110 | O4: 2435 | P4: 60 | Q4: 1330 | S4: 140 | U4: 2950 | V4: 42.5 | W4: 1845 | X4: 50
D5: 552.24 | I5: 4005.15 | K5: 630 | M5: 1300 | N5: 41 | O5: 785 | P5: 19.2 | Q5: 580 | S5: 170 | U5: 900 | W5: 1645 | X5: 640
I6: 5921.05 | K6: 222 | M6: 300 | O6: 72 | Q6: 156 | S6: 72 | U6: 216 | W6: 258
I7: 1784.08 | K7: 24 | M7: 102 | Q7: 78 | W7: 88
I8: =SUM(I2:I7) -> 25068.03
Y9: =SUM(Y2:Y7) -> 0
A16: =SUM(A2:A15) -> 3667.46 | B16: =SUM(B2:B15) -> 4568.06 | C16: =SUM(C2:C15) -> 3387.46 | D16: =SUM(D2:D15) -> 3515.12 | E16: =SUM(E2:E15) -> 205 | F16: =SUM(F2:F15) -> 3672.16 | G16: =SUM(G2:G15) -> 3152.16 | H16: =SUM(A16:G16)+I8 -> 47235.45 | I16: OASys Value | K16: =SUM(K3:K15) -> 4116 | L16: =SUM(L3:L15) -> 297.5 | M16: =SUM(M3:M15) -> 4562 | N16: =SUM(N3:N15) -> 175 | O16: =SUM(O3:O15) -> 4592 | P16: =SUM(P3:P15) -> 209.2 | Q16: =SUM(Q3:Q15) -> 2924 | R16: =SUM(R3:R15) -> 42.5 | ... X16: =SUM(X3:X15) -> 690 | Y16: =K17+M17+O17+Q17+S17+U17+W17 -> 29808
A17: 3667.46 | B17: 4568.06 | C17: 3387.46 | D17: 2962.88 | E17: 205 | F17: 3672.16 | G17: 3152.16 | H17: =SUM(A17:G17)+I8 -> 46683.21 | I17: Payroll Value | K17: 4116 | L17: 297.5 | M17: 4562 | N17: 175 | O17: 4592 | P17: 209.2 | Q17: 2924 | R17: 42.5 | S17: 862 | T17: 0 | U17: 6286 | V17: 414.5 | W17: 6466 | X17: 690 | Y17: =L17+N17+P17+R17+T17+V17+X17 -> 1828.7
